Workbook

Sheet 0.작성안내
B2: BYN 근태 기준정보 통합 사전질의서
B3: JaDE HR 시스템 구축 / 근태 영역 기준정보 확정을 위한 회신 요청
B5: 작성 목적 | C5: 근태 영역 기준정보(근태코드 / 근무유형 / 근로유형 / 스케줄근무그룹 / 신청서)를 확정하기 위한 질의서입니다. HCG가 1차로 설정한 안을 함께 기재하였습니다. 그대로 진행할지, 수정이 필요한지 회신해 주시면 그 내용을 기준으로 시스템 설정 및 설계를 진행합니다.
B6: 회신 방법 | C6: 노란색 입력칸에만 작성해 주십시오. 회색 칸은 HCG 설정안 또는 안내문이므로 작성이 불필요합니다. 판단이 어려운 항목은 비고란에 사유를 남겨 주시면 담당 컨설턴트가 협의드립니다.
B7: 회신 기한 | C7: 2026.09.11(금) 까지
B9: 시트 구성
B10: 1.근태코드 | C10: BYN 기준으로 정리한 근태코드 14종(예시)입니다. 생성근태 여부와 부여기준을 회신해 주십시오.
B11: 2-1.근무유형 | C11: 하루 단위 계획시간 목록입니다. 이 시트가 마스터이며 2-2 / 2-3은 여기에 자동 연동됩니다.
B12: 2-2.근태코드 시간 | C12: 근무유형별 반차 시간대입니다. 2-1의 계획시간에 따라 자동 산출됩니다.
B13: 2-3.지각조퇴 | C13: 근무유형별 지각 / 조퇴 기준입니다. 기준시각은 2-1에서 자동 연동됩니다.
B14: 3.근로유형(정산) | C14: 정산 단위 기준입니다. 소정근로시간, 연장 인정시간, 대체휴가 부여기준을 회신해 주십시오.
B15: 4.스케줄근무그룹 | C15: 스케줄근무를 운영해야 하는 근무유형을 그룹 단위로 반영해 주십시오.
B16: 5.신청서_근태코드 | C16: 신청서 종류와 신청서별로 선택 가능한 근태코드를 연결해 주십시오.
B17: 참조_근태코드 | C17: 드롭다운 원본 목록입니다. 수정하지 마십시오.
B19: 색상 범례
B20: 노란색 | C20: 고객사 작성(입력 / 선택) 칸입니다.
B21: 연두색 | C21: HCG 설정안입니다. 그대로 진행 시 별도 작성이 불필요합니다.
B22: 회색 | C22: 개념 설명 / 안내문입니다. 작성 불필요합니다.
B23: 연파랑 | C23: 항목 구분 머리글입니다. 작성 불필요합니다.

Sheet 1.근태코드
B2: 1. 근태코드 확정 / 생성근태 여부 확인
B4: [생성근태(부여-차감형 근태)란] 사용 전에 별도의 부여(생성) 절차를 통해 개인별 사용 가능 일수가 먼저 만들어지고, 신청할 때마다 그 잔여일수에서 차감되는 근태를 말합니다. 생성근태로 지정하면 부여일수 / 사용일수 / 잔여일수가 관리되고, 잔여가 없으면 신청이 제한됩니다. 미지정 시에는 잔여 관리 없이 신청만 가능합니다. 예) 연차휴가 - 매년 15일 부여 후 사용할 때마다 차감 => 생성근태 O / 경조휴가 - 사유 발생 시 규정 일수만큼 신청 => 생성근태 X ※ 반차와 같이 상위 근태(연차휴가)의 잔여에서 차감되는 코드는 그 자체를 생성근태로 두지 않고, 차감근태 항목에 상위 코드를 연결합니다.
B5: [HCG 설정안] 취업규칙 및 제주 근무표를 기준으로 근태코드 14종을 정리하였습니다. 지각 / 조퇴 / 외출 / 연장 등 근무(시간) 코드는 신청서 대상이 아니므로 제외하였습니다. [회신 요청] 생성근태 여부 칸에서 ☑(생성함) / ☐(생성하지 않음)을 선택해 주십시오. ☑ 선택 시 부여기준 칸에 부여 방식(부여 시점 / 일수 / 이월 여부)을 함께 기재해 주십시오. [미확정 안내] 아래 14종은 확정본이 아닙니다. 추가가 필요한 근태코드는 표 하단의 빈 행에 직접 기재해 주시고, 삭제 / 명칭 변경이 필요한 항목은 비고란에 기재해 주십시오.
B7: No | C7: 근태코드 | D7: 코드명 | E7: 근태(일) | F7: 근무(시간) | G7: 차감근태 | H7: 적용(차감) 일수 | I7: 생성근태 여부 (선택) | J7: 부여기준 (생성근태인 경우 작성) | K7: 비고 / 변경요청
B8: 1 | C8: 4100 | D8: 연차휴가 | E8: Y | F8: N | G8: 연차휴가 | H8: 1 | I8: ☑ | J8: ex) 매년 1/1 일괄부여 / 입사 1년 미만 월 1일 / 이월 여부 Y
B9: 2 | C9: 4110 | D9: 반차(오전) | E9: Y | F9: N | G9: 연차휴가 | H9: 0.5 | I9: ☐
B10: 3 | C10: 4120 | D10: 반차(오후) | E10: Y | F10: N | G10: 연차휴가 | H10: 0.5 | I10: ☐
B11: 4 | C11: 6100 | D11: 대체휴무 | E11: Y | F11: N | G11: 대체휴무 | H11: 1 | I11: ☑
B12: 5 | C12: 5000 | D12: 경조휴가 | E12: Y | F12: N | H12: 1 | I12: ☐
B13: 6 | C13: 5100 | D13: 공가 | E13: Y | F13: N | H13: 1 | I13: ☐
B14: 7 | C14: 5200 | D14: 생리휴가 | E14: Y | F14: N | H14: 1 | I14: ☐
B15: 8 | C15: 5300 | D15: 출산전후휴가 | E15: Y | F15: N | H15: 1 | I15: ☐
B16: 9 | C16: 5310 | D16: 유산/사산휴가 | E16: Y | F16: N | H16: 1 | I16: ☐
B17: 10 | C17: 5400 | D17: 배우자출산휴가 | E17: Y | F17: N | H17: 1 | I17: ☐
B18: 11 | C18: 5500 | D18: 난임휴가 | E18: Y | F18: N | H18: 1 | I18: ☐
B19: 12 | C19: 5800 | D19: 가족돌봄휴가 | E19: Y | F19: N | H19: 1 | I19: ☐
B20: 13 | C20: 2000 | D20: 교육 | E20: N | F20: Y | H20: 1 | I20: ☐
B21: 14 | C21: 2100 | D21: 출장 | E21: Y | F21: N | H21: 1 | I21: ☐
B22: 15 | D22: (추가하실 근태코드를 작성해 주세요) | I22: ☐
B23: 16 | D23: (추가하실 근태코드를 작성해 주세요) | I23: ☐
B24: 17 | D24: (추가하실 근태코드를 작성해 주세요) | I24: ☐
B25: 18 | D25: (추가하실 근태코드를 작성해 주세요) | I25: ☐
B26: 19 | D26: (추가하실 근태코드를 작성해 주세요) | I26: ☐
B27: 20 | D27: (추가하실 근태코드를 작성해 주세요) | I27: ☐
B28: 21 | D28: (추가하실 근태코드를 작성해 주세요) | I28: ☐
B29: 22 | D29: (추가하실 근태코드를 작성해 주세요) | I29: ☐
B30: 23 | D30: (추가하실 근태코드를 작성해 주세요) | I30: ☐
B31: 24 | D31: (추가하실 근태코드를 작성해 주세요) | I31: ☐

Sheet 2-1.근무유형
B2: 2-1. 근무유형(Day) 목록 - 명칭 / 계획시간 / 휴게시간
B4: [근무유형이란] 하루(Day) 단위의 근무 스케줄입니다. 출근 예정시각 / 퇴근 예정시각 / 휴게시간 / 소정근무시간을 정의하며, 실제 출퇴근 기록은 이 계획시간과 비교되어 지각 / 조퇴 / 연장이 판정됩니다. [HCG 설정안] 취업규칙(기본 09:00-18:00 / 시차출퇴근 / 재택), 모성보호 단축근무, 제주 야크마을 근무표의 교대코드를 반영하여 아래와 같이 구성하였습니다. 제주 교대는 근무표에 표기되는 교대코드를 명칭 앞에 두고 계획시간을 괄호로 표기하였습니다. 시간이 같아도 파트별 표기가 다른 경우(I)는 별도 유형으로 분리하였습니다. [회신 요청] 사용여부에 ☑ / ☐를 표시하고, 제주 교대조의 휴게시간(시작 / 종료)을 기재해 주십시오. 없는 유형은 빈 행에 추가 기재해 주십시오. ※ 이 시트가 근무유형 마스터입니다. 여기에 근무유형을 추가하거나 계획시간을 수정하시면 2-2와 2-3의 해당 행에 자동으로 반영됩니다.
B6: No | C6: 사용여부 (선택) | D6: 구분 | E6: 근무유형 명칭 | F6: 근무형태 | G6: 출근시각 | H6: 퇴근시각 | I6: 휴게 시작 | J6: 휴게 종료 | K6: 휴게시간 (분) | L6: 소정근무 시간 | M6: 비고 (적용 대상 / 근거)
B7: 1 | C7: ☑ | D7: 본사 / 물류 | E7: 기본(09:00-18:00) | F7: 평일 | G7: 09:00 | H7: 18:00 | I7: 12:00 | J7: 13:00 | K7: 60 | L7: 8
B8: 2 | C8: ☑ | D8: 본사 / 물류 | E8: 시차(08:00-17:00) | F8: 평일 | G8: 08:00 | H8: 17:00 | I8: 12:00 | J8: 13:00 | K8: 60 | L8: 8
B9: 3 | C9: ☑ | D9: 본사 / 물류 | E9: 재택(09:00-18:00) | F9: 평일 | G9: 09:00 | H9: 18:00 | I9: 12:00 | J9: 13:00 | K9: 60 | L9: 8
B10: 4 | C10: ☑ | D10: 모성보호 | E10: 임신기단축(08:00-15:00) | F10: 평일 | G10: 08:00 | H10: 15:00 | I10: 12:00 | J10: 13:00 | K10: 60 | L10: 6
B11: 5 | C11: ☑ | D11: 모성보호 | E11: 임신기단축(09:00-16:00) | F11: 평일 | G11: 09:00 | H11: 16:00 | I11: 12:00 | J11: 13:00 | K11: 60 | L11: 6
B12: 6 | C12: ☑ | D12: 모성보호 | E12: 임신기단축(10:00-17:00) | F12: 평일 | G12: 10:00 | H12: 17:00 | I12: 12:00 | J12: 13:00 | K12: 60 | L12: 6
B13: 7 | C13: ☑ | D13: 모성보호 | E13: 임신기단축(11:00-18:00) | F13: 평일 | G13: 11:00 | H13: 18:00 | I13: 12:00 | J13: 13:00 | K13: 60 | L13: 6
B14: 8 | C14: ☑ | D14: 모성보호 | E14: 육아기단축(09:00-17:00) | F14: 평일 | G14: 09:00 | H14: 17:00 | I14: 12:00 | J14: 13:00 | K14: 60 | L14: 7
B15: 9 | C15: ☑ | D15: 모성보호 | E15: 육아기단축(09:00-16:00) | F15: 평일 | G15: 09:00 | H15: 16:00 | I15: 12:00 | J15: 13:00 | K15: 60 | L15: 6
B16: 10 | C16: ☑ | D16: 모성보호 | E16: 육아기단축(09:00-15:00) | F16: 평일 | G16: 09:00 | H16: 15:00 | I16: 12:00 | J16: 13:00 | K16: 60 | L16: 5
B17: 11 | C17: ☑ | D17: 제주 교대 | E17: A(06:00-15:00) | F17: 평일 | G17: 06:00 | H17: 15:00 | K17: 60 | L17: 8
B18: 12 | C18: ☑ | D18: 제주 교대 | E18: B(07:00-16:00) | F18: 평일 | G18: 07:00 | H18: 16:00 | K18: 60 | L18: 8
B19: 13 | C19: ☑ | D19: 제주 교대 | E19: B1(07:30-16:30) | F19: 평일 | G19: 07:30 | H19: 16:30 | K19: 60 | L19: 8
B20: 14 | C20: ☑ | D20: 제주 교대 | E20: C(08:00-17:00) | F20: 평일 | G20: 08:00 | H20: 17:00 | K20: 60 | L20: 8
B21: 15 | C21: ☑ | D21: 제주 교대 | E21: C1(08:30-17:30) | F21: 평일 | G21: 08:30 | H21: 17:30 | K21: 60 | L21: 8
B22: 16 | C22: ☑ | D22: 제주 교대 | E22: D(09:00-18:00) | F22: 평일 | G22: 09:00 | H22: 18:00 | K22: 60 | L22: 8
B23: 17 | C23: ☑ | D23: 제주 교대 | E23: E(10:00-19:00) | F23: 평일 | G23: 10:00 | H23: 19:00 | K23: 60 | L23: 8
B24: 18 | C24: ☑ | D24: 제주 교대 | E24: F(11:00-20:00) | F24: 평일 | G24: 11:00 | H24: 20:00 | K24: 60 | L24: 8
B25: 19 | C25: ☑ | D25: 제주 교대 | E25: G(12:00-21:00) | F25: 평일 | G25: 12:00 | H25: 21:00 | K25: 60 | L25: 8
B26: 20 | C26: ☑ | D26: 제주 교대 | E26: H(13:00-22:00) | F26: 평일 | G26: 13:00 | H26: 22:00 | K26: 60 | L26: 8
B27: 21 | C27: ☑ | D27: 제주 교대 | E27: I(13:00-22:00) | F27: 평일 | G27: 13:00 | H27: 22:00 | K27: 60 | L27: 8
B28: 22 | C28: ☑ | D28: 제주 교대 | E28: I(14:00-23:00) | F28: 평일 | G28: 14:00 | H28: 23:00 | K28: 60 | L28: 8
B29: 23 | C29: ☑ | D29: 제주 교대 | E29: R(23:00-익일08:00) | F29: 평일 | G29: 23:00 | H29: 08:00 | K29: 60 | L29: 8
B30: 24 | C30: ☑ | D30: 제주 교대 | E30: 야(13:00-익일09:00) | F30: 평일 | G30: 13:00 | H30: 09:00
B31: 25 | C31: ☑ | D31: 제주 교대 | E31: 비(비번) | F31: 평일
B32: 26 | C32: ☑ | D32: 공통 | E32: 휴일 | F32: 공휴
B33: 27 | C33: ☑ | D33: 공통 | E33: 휴무 | F33: 공휴
B34: 28 | C34: ☐ | E34: (추가하실 근무유형을 작성해 주세요)
B35: 29 | C35: ☐ | E35: (추가하실 근무유형을 작성해 주세요)
B36: 30 | C36: ☐ | E36: (추가하실 근무유형을 작성해 주세요)
B37: 31 | C37: ☐ | E37: (추가하실 근무유형을 작성해 주세요)
B38: 32 | C38: ☐ | E38: (추가하실 근무유형을 작성해 주세요)
B39: 33 | C39: ☐ | E39: (추가하실 근무유형을 작성해 주세요)
B40: 34 | C40: ☐ | E40: (추가하실 근무유형을 작성해 주세요)
B41: 35 | C41: ☐ | E41: (추가하실 근무유형을 작성해 주세요)
B42: 36 | C42: ☐ | E42: (추가하실 근무유형을 작성해 주세요)
B43: 37 | C43: ☐ | E43: (추가하실 근무유형을 작성해 주세요)
...

Sheet 2-2.근태코드 시간
B2: 2-2. 근무유형별 근태코드 시간 정의
B4: [자동 연동] 근무유형 명칭 / 계획 근무시간 / 반차 시간대는 2-1.근무유형 시트에서 자동으로 가져옵니다. 2-1에 근무유형을 추가하거나 계획시간을 수정하시면 이 시트의 같은 행에 자동 반영되므로, 이 시트에서 명칭을 직접 수정하지 마십시오. [산출 기준] 오전 반차는 출근시각부터, 오후 반차는 퇴근시각까지이며 경계시각은 소정근무시간의 절반 지점으로 계산합니다. 휴게시간이 오전 구간에 포함되면 그만큼 뒤로 밀어 계산합니다. [회신 요청] 자동 산출된 시간대가 실제 운영과 다르면 비고란에 수정 시각을 기재해 주십시오. 제주 교대조는 2-1에서 휴게시간을 기재하셔야 값이 채워집니다.
B6: No | C6: 근무유형 명칭 | D6: 계획 근무시간 | E6: 4110 반차(오전) | G6: 4120 반차(오후) | I6: 비고 / 수정요청
E7: 시작 | F7: 종료 | G7: 시작 | H7: 종료
B8: 1 | C8: =IF(OR('2-1.근무유형'!E7="",LEFT('2-1.근무유형'!E7,1)="("),"",'2-1.근무유형'!E7) -> 기본(09:00-18:00) | D8: =IF(OR('2-1.근무유형'!G7="",'2-1.근무유형'!H7=""),"",'2-1.근무유형'!G7&"-"&'2-1.근무유형'!H7) -> 09:00-18:00 | E8: =IF('2-1.근무유형'!G7="","",'2-1.근무유형'!G7) -> 09:00 | F8: =IFERROR(IF(OR('2-1.근무유형'!G7="",'2-1.근무유형'!H7="",'2-1.근무유형'!K7="",TIMEVALUE('2-1.근무유형'!H7)<=TIMEVALUE('2-1.근무유형'!G7)),"",TEXT(TIMEVALUE('2-1.근무유형'!G7)+(TIMEVALUE('2-1.근무유형'!H7)-TIMEVALUE('2-1.근무유형'!G7)-'2-1.근무유형'!K7/1440)/2+IF(AND('2-1.근무유형'!I7<>"",TIMEVALUE('2-1.근무유형'!I7)>=TIMEVALUE('2-1.근무유형'!G7),TIMEVALUE('2-1.근무유형'!I7)<TIMEVALUE('2-1.근무유형'!G7)+(TIMEVALUE('2-1.근무유형'!H7)-TIMEVALUE('2-1.근무유형'!G7)-'2-1.근무유형'!K7/1440)/2+'2-1.근무유형'!K7/1440),'2-1.근무유형'!K7/1440,0),"hh:mm")),"") -> 14:00 | G8: =F8 -> 14:00 | H8: =IF('2-1.근무유형'!H7="","",'2-1.근무유형'!H7) -> 18:00
B9: 2 | C9: =IF(OR('2-1.근무유형'!E8="",LEFT('2-1.근무유형'!E8,1)="("),"",'2-1.근무유형'!E8) -> 시차(08:00-17:00) | D9: =IF(OR('2-1.근무유형'!G8="",'2-1.근무유형'!H8=""),"",'2-1.근무유형'!G8&"-"&'2-1.근무유형'!H8) -> 08:00-17:00 | E9: =IF('2-1.근무유형'!G8="","",'2-1.근무유형'!G8) -> 08:00 | F9: =IFERROR(IF(OR('2-1.근무유형'!G8="",'2-1.근무유형'!H8="",'2-1.근무유형'!K8="",TIMEVALUE('2-1.근무유형'!H8)<=TIMEVALUE('2-1.근무유형'!G8)),"",TEXT(TIMEVALUE('2-1.근무유형'!G8)+(TIMEVALUE('2-1.근무유형'!H8)-TIMEVALUE('2-1.근무유형'!G8)-'2-1.근무유형'!K8/1440)/2+IF(AND('2-1.근무유형'!I8<>"",TIMEVALUE('2-1.근무유형'!I8)>=TIMEVALUE('2-1.근무유형'!G8),TIMEVALUE('2-1.근무유형'!I8)<TIMEVALUE('2-1.근무유형'!G8)+(TIMEVALUE('2-1.근무유형'!H8)-TIMEVALUE('2-1.근무유형'!G8)-'2-1.근무유형'!K8/1440)/2+'2-1.근무유형'!K8/1440),'2-1.근무유형'!K8/1440,0),"hh:mm")),"") -> 13:00 | G9: =F9 -> 13:00 | H9: =IF('2-1.근무유형'!H8="","",'2-1.근무유형'!H8) -> 17:00
B10: 3 | C10: =IF(OR('2-1.근무유형'!E9="",LEFT('2-1.근무유형'!E9,1)="("),"",'2-1.근무유형'!E9) -> 재택(09:00-18:00) | D10: =IF(OR('2-1.근무유형'!G9="",'2-1.근무유형'!H9=""),"",'2-1.근무유형'!G9&"-"&'2-1.근무유형'!H9) -> 09:00-18:00 | E10: =IF('2-1.근무유형'!G9="","",'2-1.근무유형'!G9) -> 09:00 | F10: =IFERROR(IF(OR('2-1.근무유형'!G9="",'2-1.근무유형'!H9="",'2-1.근무유형'!K9="",TIMEVALUE('2-1.근무유형'!H9)<=TIMEVALUE('2-1.근무유형'!G9)),"",TEXT(TIMEVALUE('2-1.근무유형'!G9)+(TIMEVALUE('2-1.근무유형'!H9)-TIMEVALUE('2-1.근무유형'!G9)-'2-1.근무유형'!K9/1440)/2+IF(AND('2-1.근무유형'!I9<>"",TIMEVALUE('2-1.근무유형'!I9)>=TIMEVALUE('2-1.근무유형'!G9),TIMEVALUE('2-1.근무유형'!I9)<TIMEVALUE('2-1.근무유형'!G9)+(TIMEVALUE('2-1.근무유형'!H9)-TIMEVALUE('2-1.근무유형'!G9)-'2-1.근무유형'!K9/1440)/2+'2-1.근무유형'!K9/1440),'2-1.근무유형'!K9/1440,0),"hh:mm")),"") -> 14:00 | G10: =F10 -> 14:00 | H10: =IF('2-1.근무유형'!H9="","",'2-1.근무유형'!H9) -> 18:00
B11: 4 | C11: =IF(OR('2-1.근무유형'!E10="",LEFT('2-1.근무유형'!E10,1)="("),"",'2-1.근무유형'!E10) -> 임신기단축(08:00-15:00) | D11: =IF(OR('2-1.근무유형'!G10="",'2-1.근무유형'!H10=""),"",'2-1.근무유형'!G10&"-"&'2-1.근무유형'!H10) -> 08:00-15:00 | E11: =IF('2-1.근무유형'!G10="","",'2-1.근무유형'!G10) -> 08:00 | F11: =IFERROR(IF(OR('2-1.근무유형'!G10="",'2-1.근무유형'!H10="",'2-1.근무유형'!K10="",TIMEVALUE('2-1.근무유형'!H10)<=TIMEVALUE('2-1.근무유형'!G10)),"",TEXT(TIMEVALUE('2-1.근무유형'!G10)+(TIMEVALUE('2-1.근무유형'!H10)-TIMEVALUE('2-1.근무유형'!G10)-'2-1.근무유형'!K10/1440)/2+IF(AND('2-1.근무유형'!I10<>"",TIMEVALUE('2-1.근무유형'!I10)>=TIMEVALUE('2-1.근무유형'!G10),TIMEVALUE('2-1.근무유형'!I10)<TIMEVALUE('2-1.근무유형'!G10)+(TIMEVALUE('2-1.근무유형'!H10)-TIMEVALUE('2-1.근무유형'!G10)-'2-1.근무유형'!K10/1440)/2+'2-1.근무유형'!K10/1440),'2-1.근무유형'!K10/1440,0),"hh:mm")),"") -> 11:00 | G11: =F11 -> 11:00 | H11: =IF('2-1.근무유형'!H10="","",'2-1.근무유형'!H10) -> 15:00
B12: 5 | C12: =IF(OR('2-1.근무유형'!E11="",LEFT('2-1.근무유형'!E11,1)="("),"",'2-1.근무유형'!E11) -> 임신기단축(09:00-16:00) | D12: =IF(OR('2-1.근무유형'!G11="",'2-1.근무유형'!H11=""),"",'2-1.근무유형'!G11&"-"&'2-1.근무유형'!H11) -> 09:00-16:00 | E12: =IF('2-1.근무유형'!G11="","",'2-1.근무유형'!G11) -> 09:00 | F12: =IFERROR(IF(OR('2-1.근무유형'!G11="",'2-1.근무유형'!H11="",'2-1.근무유형'!K11="",TIMEVALUE('2-1.근무유형'!H11)<=TIMEVALUE('2-1.근무유형'!G11)),"",TEXT(TIMEVALUE('2-1.근무유형'!G11)+(TIMEVALUE('2-1.근무유형'!H11)-TIMEVALUE('2-1.근무유형'!G11)-'2-1.근무유형'!K11/1440)/2+IF(AND('2-1.근무유형'!I11<>"",TIMEVALUE('2-1.근무유형'!I11)>=TIMEVALUE('2-1.근무유형'!G11),TIMEVALUE('2-1.근무유형'!I11)<TIMEVALUE('2-1.근무유형'!G11)+(TIMEVALUE('2-1.근무유형'!H11)-TIMEVALUE('2-1.근무유형'!G11)-'2-1.근무유형'!K11/1440)/2+'2-1.근무유형'!K11/1440),'2-1.근무유형'!K11/1440,0),"hh:mm")),"") -> 13:00 | G12: =F12 -> 13:00 | H12: =IF('2-1.근무유형'!H11="","",'2-1.근무유형'!H11) -> 16:00
B13: 6 | C13: =IF(OR('2-1.근무유형'!E12="",LEFT('2-1.근무유형'!E12,1)="("),"",'2-1.근무유형'!E12) -> 임신기단축(10:00-17:00) | D13: =IF(OR('2-1.근무유형'!G12="",'2-1.근무유형'!H12=""),"",'2-1.근무유형'!G12&"-"&'2-1.근무유형'!H12) -> 10:00-17:00 | E13: =IF('2-1.근무유형'!G12="","",'2-1.근무유형'!G12) -> 10:00 | F13: =IFERROR(IF(OR('2-1.근무유형'!G12="",'2-1.근무유형'!H12="",'2-1.근무유형'!K12="",TIMEVALUE('2-1.근무유형'!H12)<=TIMEVALUE('2-1.근무유형'!G12)),"",TEXT(TIMEVALUE('2-1.근무유형'!G12)+(TIMEVALUE('2-1.근무유형'!H12)-TIMEVALUE('2-1.근무유형'!G12)-'2-1.근무유형'!K12/1440)/2+IF(AND('2-1.근무유형'!I12<>"",TIMEVALUE('2-1.근무유형'!I12)>=TIMEVALUE('2-1.근무유형'!G12),TIMEVALUE('2-1.근무유형'!I12)<TIMEVALUE('2-1.근무유형'!G12)+(TIMEVALUE('2-1.근무유형'!H12)-TIMEVALUE('2-1.근무유형'!G12)-'2-1.근무유형'!K12/1440)/2+'2-1.근무유형'!K12/1440),'2-1.근무유형'!K12/1440,0),"hh:mm")),"") -> 14:00 | G13: =F13 -> 14:00 | H13: =IF('2-1.근무유형'!H12="","",'2-1.근무유형'!H12) -> 17:00
B14: 7 | C14: =IF(OR('2-1.근무유형'!E13="",LEFT('2-1.근무유형'!E13,1)="("),"",'2-1.근무유형'!E13) -> 임신기단축(11:00-18:00) | D14: =IF(OR('2-1.근무유형'!G13="",'2-1.근무유형'!H13=""),"",'2-1.근무유형'!G13&"-"&'2-1.근무유형'!H13) -> 11:00-18:00 | E14: =IF('2-1.근무유형'!G13="","",'2-1.근무유형'!G13) -> 11:00 | F14: =IFERROR(IF(OR('2-1.근무유형'!G13="",'2-1.근무유형'!H13="",'2-1.근무유형'!K13="",TIMEVALUE('2-1.근무유형'!H13)<=TIMEVALUE('2-1.근무유형'!G13)),"",TEXT(TIMEVALUE('2-1.근무유형'!G13)+(TIMEVALUE('2-1.근무유형'!H13)-TIMEVALUE('2-1.근무유형'!G13)-'2-1.근무유형'!K13/1440)/2+IF(AND('2-1.근무유형'!I13<>"",TIMEVALUE('2-1.근무유형'!I13)>=TIMEVALUE('2-1.근무유형'!G13),TIMEVALUE('2-1.근무유형'!I13)<TIMEVALUE('2-1.근무유형'!G13)+(TIMEVALUE('2-1.근무유형'!H13)-TIMEVALUE('2-1.근무유형'!G13)-'2-1.근무유형'!K13/1440)/2+'2-1.근무유형'!K13/1440),'2-1.근무유형'!K13/1440,0),"hh:mm")),"") -> 15:00 | G14: =F14 -> 15:00 | H14: =IF('2-1.근무유형'!H13="","",'2-1.근무유형'!H13) -> 18:00
B15: 8 | C15: =IF(OR('2-1.근무유형'!E14="",LEFT('2-1.근무유형'!E14,1)="("),"",'2-1.근무유형'!E14) -> 육아기단축(09:00-17:00) | D15: =IF(OR('2-1.근무유형'!G14="",'2-1.근무유형'!H14=""),"",'2-1.근무유형'!G14&"-"&'2-1.근무유형'!H14) -> 09:00-17:00 | E15: =IF('2-1.근무유형'!G14="","",'2-1.근무유형'!G14) -> 09:00 | F15: =IFERROR(IF(OR('2-1.근무유형'!G14="",'2-1.근무유형'!H14="",'2-1.근무유형'!K14="",TIMEVALUE('2-1.근무유형'!H14)<=TIMEVALUE('2-1.근무유형'!G14)),"",TEXT(TIMEVALUE('2-1.근무유형'!G14)+(TIMEVALUE('2-1.근무유형'!H14)-TIMEVALUE('2-1.근무유형'!G14)-'2-1.근무유형'!K14/1440)/2+IF(AND('2-1.근무유형'!I14<>"",TIMEVALUE('2-1.근무유형'!I14)>=TIMEVALUE('2-1.근무유형'!G14),TIMEVALUE('2-1.근무유형'!I14)<TIMEVALUE('2-1.근무유형'!G14)+(TIMEVALUE('2-1.근무유형'!H14)-TIMEVALUE('2-1.근무유형'!G14)-'2-1.근무유형'!K14/1440)/2+'2-1.근무유형'!K14/1440),'2-1.근무유형'!K14/1440,0),"hh:mm")),"") -> 13:30 | G15: =F15 -> 13:30 | H15: =IF('2-1.근무유형'!H14="","",'2-1.근무유형'!H14) -> 17:00
B16: 9 | C16: =IF(OR('2-1.근무유형'!E15="",LEFT('2-1.근무유형'!E15,1)="("),"",'2-1.근무유형'!E15) -> 육아기단축(09:00-16:00) | D16: =IF(OR('2-1.근무유형'!G15="",'2-1.근무유형'!H15=""),"",'2-1.근무유형'!G15&"-"&'2-1.근무유형'!H15) -> 09:00-16:00 | E16: =IF('2-1.근무유형'!G15="","",'2-1.근무유형'!G15) -> 09:00 | F16: =IFERROR(IF(OR('2-1.근무유형'!G15="",'2-1.근무유형'!H15="",'2-1.근무유형'!K15="",TIMEVALUE('2-1.근무유형'!H15)<=TIMEVALUE('2-1.근무유형'!G15)),"",TEXT(TIMEVALUE('2-1.근무유형'!G15)+(TIMEVALUE('2-1.근무유형'!H15)-TIMEVALUE('2-1.근무유형'!G15)-'2-1.근무유형'!K15/1440)/2+IF(AND('2-1.근무유형'!I15<>"",TIMEVALUE('2-1.근무유형'!I15)>=TIMEVALUE('2-1.근무유형'!G15),TIMEVALUE('2-1.근무유형'!I15)<TIMEVALUE('2-1.근무유형'!G15)+(TIMEVALUE('2-1.근무유형'!H15)-TIMEVALUE('2-1.근무유형'!G15)-'2-1.근무유형'!K15/1440)/2+'2-1.근무유형'!K15/1440),'2-1.근무유형'!K15/1440,0),"hh:mm")),"") -> 13:00 | G16: =F16 -> 13:00 | H16: =IF('2-1.근무유형'!H15="","",'2-1.근무유형'!H15) -> 16:00
B17: 10 | C17: =IF(OR('2-1.근무유형'!E16="",LEFT('2-1.근무유형'!E16,1)="("),"",'2-1.근무유형'!E16) -> 육아기단축(09:00-15:00) | D17: =IF(OR('2-1.근무유형'!G16="",'2-1.근무유형'!H16=""),"",'2-1.근무유형'!G16&"-"&'2-1.근무유형'!H16) -> 09:00-15:00 | E17: =IF('2-1.근무유형'!G16="","",'2-1.근무유형'!G16) -> 09:00 | F17: =IFERROR(IF(OR('2-1.근무유형'!G16="",'2-1.근무유형'!H16="",'2-1.근무유형'!K16="",TIMEVALUE('2-1.근무유형'!H16)<=TIMEVALUE('2-1.근무유형'!G16)),"",TEXT(TIMEVALUE('2-1.근무유형'!G16)+(TIMEVALUE('2-1.근무유형'!H16)-TIMEVALUE('2-1.근무유형'!G16)-'2-1.근무유형'!K16/1440)/2+IF(AND('2-1.근무유형'!I16<>"",TIMEVALUE('2-1.근무유형'!I16)>=TIMEVALUE('2-1.근무유형'!G16),TIMEVALUE('2-1.근무유형'!I16)<TIMEVALUE('2-1.근무유형'!G16)+(TIMEVALUE('2-1.근무유형'!H16)-TIMEVALUE('2-1.근무유형'!G16)-'2-1.근무유형'!K16/1440)/2+'2-1.근무유형'!K16/1440),'2-1.근무유형'!K16/1440,0),"hh:mm")),"") -> 12:30 | G17: =F17 -> 12:30 | H17: =IF('2-1.근무유형'!H16="","",'2-1.근무유형'!H16) -> 15:00
B18: 11 | C18: =IF(OR('2-1.근무유형'!E17="",LEFT('2-1.근무유형'!E17,1)="("),"",'2-1.근무유형'!E17) -> A(06:00-15:00) | D18: =IF(OR('2-1.근무유형'!G17="",'2-1.근무유형'!H17=""),"",'2-1.근무유형'!G17&"-"&'2-1.근무유형'!H17) -> 06:00-15:00 | E18: =IF('2-1.근무유형'!G17="","",'2-1.근무유형'!G17) -> 06:00 | F18: =IFERROR(IF(OR('2-1.근무유형'!G17="",'2-1.근무유형'!H17="",'2-1.근무유형'!K17="",TIMEVALUE('2-1.근무유형'!H17)<=TIMEVALUE('2-1.근무유형'!G17)),"",TEXT(TIMEVALUE('2-1.근무유형'!G17)+(TIMEVALUE('2-1.근무유형'!H17)-TIMEVALUE('2-1.근무유형'!G17)-'2-1.근무유형'!K17/1440)/2+IF(AND('2-1.근무유형'!I17<>"",TIMEVALUE('2-1.근무유형'!I17)>=TIMEVALUE('2-1.근무유형'!G17),TIMEVALUE('2-1.근무유형'!I17)<TIMEVALUE('2-1.근무유형'!G17)+(TIMEVALUE('2-1.근무유형'!H17)-TIMEVALUE('2-1.근무유형'!G17)-'2-1.근무유형'!K17/1440)/2+'2-1.근무유형'!K17/1440),'2-1.근무유형'!K17/1440,0),"hh:mm")),"") | G18: =F18 | H18: =IF('2-1.근무유형'!H17="","",'2-1.근무유형'!H17) -> 15:00
B19: 12 | C19: =IF(OR('2-1.근무유형'!E18="",LEFT('2-1.근무유형'!E18,1)="("),"",'2-1.근무유형'!E18) -> B(07:00-16:00) | D19: =IF(OR('2-1.근무유형'!G18="",'2-1.근무유형'!H18=""),"",'2-1.근무유형'!G18&"-"&'2-1.근무유형'!H18) -> 07:00-16:00 | E19: =IF('2-1.근무유형'!G18="","",'2-1.근무유형'!G18) -> 07:00 | F19: =IFERROR(IF(OR('2-1.근무유형'!G18="",'2-1.근무유형'!H18="",'2-1.근무유형'!K18="",TIMEVALUE('2-1.근무유형'!H18)<=TIMEVALUE('2-1.근무유형'!G18)),"",TEXT(TIMEVALUE('2-1.근무유형'!G18)+(TIMEVALUE('2-1.근무유형'!H18)-TIMEVALUE('2-1.근무유형'!G18)-'2-1.근무유형'!K18/1440)/2+IF(AND('2-1.근무유형'!I18<>"",TIMEVALUE('2-1.근무유형'!I18)>=TIMEVALUE('2-1.근무유형'!G18),TIMEVALUE('2-1.근무유형'!I18)<TIMEVALUE('2-1.근무유형'!G18)+(TIMEVALUE('2-1.근무유형'!H18)-TIMEVALUE('2-1.근무유형'!G18)-'2-1.근무유형'!K18/1440)/2+'2-1.근무유형'!K18/1440),'2-1.근무유형'!K18/1440,0),"hh:mm")),"") | G19: =F19 | H19: =IF('2-1.근무유형'!H18="","",'2-1.근무유형'!H18) -> 16:00
... B47: 40 | C47: =IF(OR('2-1.근무유형'!E46="",LEFT('2-1.근무유형'!E46,1)="("),"",'2-1.근무유형'!E46) | D47: =IF(OR('2-1.근무유형'!G46="",'2-1.근무유형'!H46=""),"",'2-1.근무유형'!G46&"-"&'2-1.근무유형'!H46) | E47: =IF('2-1.근무유형'!G46="","",'2-1.근무유형'!G46) | F47: =IFERROR(IF(OR('2-1.근무유형'!G46="",'2-1.근무유형'!H46="",'2-1.근무유형'!K46="",TIMEVALUE('2-1.근무유형'!H46)<=TIMEVALUE('2-1.근무유형'!G46)),"",TEXT(TIMEVALUE('2-1.근무유형'!G46)+(TIMEVALUE('2-1.근무유형'!H46)-TIMEVALUE('2-1.근무유형'!G46)-'2-1.근무유형'!K46/1440)/2+IF(AND('2-1.근무유형'!I46<>"",TIMEVALUE('2-1.근무유형'!I46)>=TIMEVALUE('2-1.근무유형'!G46),TIMEVALUE('2-1.근무유형'!I46)<TIMEVALUE('2-1.근무유형'!G46)+(TIMEVALUE('2-1.근무유형'!H46)-TIMEVALUE('2-1.근무유형'!G46)-'2-1.근무유형'!K46/1440)/2+'2-1.근무유형'!K46/1440),'2-1.근무유형'!K46/1440,0),"hh:mm")),"") | G47: =F47 | H47: =IF('2-1.근무유형'!H46="","",'2-1.근무유형'!H46)

Sheet 2-3.지각조퇴
B2: 2-3. 근무유형별 지각 / 조퇴 판정 기준
B4: [자동 연동] 근무유형 명칭 / 계획 근무시간 / 지각 및 조퇴 기준시각은 2-1.근무유형 시트에서 자동으로 가져옵니다. 2-1에 근무유형을 추가하거나 계획시간을 수정하시면 이 시트의 같은 행에 자동 반영되므로, 이 시트에서 명칭을 직접 수정하지 마십시오. [회신 요청] 노란색 칸(유예시간 / 올림·버림 / 지각 판정 제외 여부)을 기재해 주십시오. 유예를 두지 않으면 0을 입력해 주십시오. 지각 기준시각 = 이 시각을 넘겨 출근하면 지각으로 판정합니다. 조퇴 기준시각 = 이 시각보다 먼저 퇴근하면 조퇴로 판정합니다. [참고] 취업규칙 제39조상 조퇴 및 외출은 무급 처리가 원칙이며, 지각에 대한 공제 기준은 별도로 정해져 있지 않습니다. 지각 공제 운영 여부를 비고란에 함께 회신해 주십시오.
B6: No | C6: 근무유형 명칭 | D6: 계획 근무시간 | E6: 지각 | H6: 조퇴 | J6: 지각 판정 제외 여부 | K6: 비고 (근무유형별 특이 규정)
E7: 기준시각 | F7: 유예(분) | G7: 올림/버림 | H7: 기준시각 | I7: 유예(분)
B8: 1 | C8: =IF(OR('2-1.근무유형'!E7="",LEFT('2-1.근무유형'!E7,1)="("),"",'2-1.근무유형'!E7) -> 기본(09:00-18:00) | D8: =IF(OR('2-1.근무유형'!G7="",'2-1.근무유형'!H7=""),"",'2-1.근무유형'!G7&"-"&'2-1.근무유형'!H7) -> 09:00-18:00 | E8: =IF('2-1.근무유형'!G7="","",'2-1.근무유형'!G7) -> 09:00 | H8: =IF('2-1.근무유형'!H7="","",'2-1.근무유형'!H7) -> 18:00
B9: 2 | C9: =IF(OR('2-1.근무유형'!E8="",LEFT('2-1.근무유형'!E8,1)="("),"",'2-1.근무유형'!E8) -> 시차(08:00-17:00) | D9: =IF(OR('2-1.근무유형'!G8="",'2-1.근무유형'!H8=""),"",'2-1.근무유형'!G8&"-"&'2-1.근무유형'!H8) -> 08:00-17:00 | E9: =IF('2-1.근무유형'!G8="","",'2-1.근무유형'!G8) -> 08:00 | H9: =IF('2-1.근무유형'!H8="","",'2-1.근무유형'!H8) -> 17:00
B10: 3 | C10: =IF(OR('2-1.근무유형'!E9="",LEFT('2-1.근무유형'!E9,1)="("),"",'2-1.근무유형'!E9) -> 재택(09:00-18:00) | D10: =IF(OR('2-1.근무유형'!G9="",'2-1.근무유형'!H9=""),"",'2-1.근무유형'!G9&"-"&'2-1.근무유형'!H9) -> 09:00-18:00 | E10: =IF('2-1.근무유형'!G9="","",'2-1.근무유형'!G9) -> 09:00 | H10: =IF('2-1.근무유형'!H9="","",'2-1.근무유형'!H9) -> 18:00
B11: 4 | C11: =IF(OR('2-1.근무유형'!E10="",LEFT('2-1.근무유형'!E10,1)="("),"",'2-1.근무유형'!E10) -> 임신기단축(08:00-15:00) | D11: =IF(OR('2-1.근무유형'!G10="",'2-1.근무유형'!H10=""),"",'2-1.근무유형'!G10&"-"&'2-1.근무유형'!H10) -> 08:00-15:00 | E11: =IF('2-1.근무유형'!G10="","",'2-1.근무유형'!G10) -> 08:00 | H11: =IF('2-1.근무유형'!H10="","",'2-1.근무유형'!H10) -> 15:00
B12: 5 | C12: =IF(OR('2-1.근무유형'!E11="",LEFT('2-1.근무유형'!E11,1)="("),"",'2-1.근무유형'!E11) -> 임신기단축(09:00-16:00) | D12: =IF(OR('2-1.근무유형'!G11="",'2-1.근무유형'!H11=""),"",'2-1.근무유형'!G11&"-"&'2-1.근무유형'!H11) -> 09:00-16:00 | E12: =IF('2-1.근무유형'!G11="","",'2-1.근무유형'!G11) -> 09:00 | H12: =IF('2-1.근무유형'!H11="","",'2-1.근무유형'!H11) -> 16:00
B13: 6 | C13: =IF(OR('2-1.근무유형'!E12="",LEFT('2-1.근무유형'!E12,1)="("),"",'2-1.근무유형'!E12) -> 임신기단축(10:00-17:00) | D13: =IF(OR('2-1.근무유형'!G12="",'2-1.근무유형'!H12=""),"",'2-1.근무유형'!G12&"-"&'2-1.근무유형'!H12) -> 10:00-17:00 | E13: =IF('2-1.근무유형'!G12="","",'2-1.근무유형'!G12) -> 10:00 | H13: =IF('2-1.근무유형'!H12="","",'2-1.근무유형'!H12) -> 17:00
B14: 7 | C14: =IF(OR('2-1.근무유형'!E13="",LEFT('2-1.근무유형'!E13,1)="("),"",'2-1.근무유형'!E13) -> 임신기단축(11:00-18:00) | D14: =IF(OR('2-1.근무유형'!G13="",'2-1.근무유형'!H13=""),"",'2-1.근무유형'!G13&"-"&'2-1.근무유형'!H13) -> 11:00-18:00 | E14: =IF('2-1.근무유형'!G13="","",'2-1.근무유형'!G13) -> 11:00 | H14: =IF('2-1.근무유형'!H13="","",'2-1.근무유형'!H13) -> 18:00
B15: 8 | C15: =IF(OR('2-1.근무유형'!E14="",LEFT('2-1.근무유형'!E14,1)="("),"",'2-1.근무유형'!E14) -> 육아기단축(09:00-17:00) | D15: =IF(OR('2-1.근무유형'!G14="",'2-1.근무유형'!H14=""),"",'2-1.근무유형'!G14&"-"&'2-1.근무유형'!H14) -> 09:00-17:00 | E15: =IF('2-1.근무유형'!G14="","",'2-1.근무유형'!G14) -> 09:00 | H15: =IF('2-1.근무유형'!H14="","",'2-1.근무유형'!H14) -> 17:00
B16: 9 | C16: =IF(OR('2-1.근무유형'!E15="",LEFT('2-1.근무유형'!E15,1)="("),"",'2-1.근무유형'!E15) -> 육아기단축(09:00-16:00) | D16: =IF(OR('2-1.근무유형'!G15="",'2-1.근무유형'!H15=""),"",'2-1.근무유형'!G15&"-"&'2-1.근무유형'!H15) -> 09:00-16:00 | E16: =IF('2-1.근무유형'!G15="","",'2-1.근무유형'!G15) -> 09:00 | H16: =IF('2-1.근무유형'!H15="","",'2-1.근무유형'!H15) -> 16:00
B17: 10 | C17: =IF(OR('2-1.근무유형'!E16="",LEFT('2-1.근무유형'!E16,1)="("),"",'2-1.근무유형'!E16) -> 육아기단축(09:00-15:00) | D17: =IF(OR('2-1.근무유형'!G16="",'2-1.근무유형'!H16=""),"",'2-1.근무유형'!G16&"-"&'2-1.근무유형'!H16) -> 09:00-15:00 | E17: =IF('2-1.근무유형'!G16="","",'2-1.근무유형'!G16) -> 09:00 | H17: =IF('2-1.근무유형'!H16="","",'2-1.근무유형'!H16) -> 15:00
B18: 11 | C18: =IF(OR('2-1.근무유형'!E17="",LEFT('2-1.근무유형'!E17,1)="("),"",'2-1.근무유형'!E17) -> A(06:00-15:00) | D18: =IF(OR('2-1.근무유형'!G17="",'2-1.근무유형'!H17=""),"",'2-1.근무유형'!G17&"-"&'2-1.근무유형'!H17) -> 06:00-15:00 | E18: =IF('2-1.근무유형'!G17="","",'2-1.근무유형'!G17) -> 06:00 | H18: =IF('2-1.근무유형'!H17="","",'2-1.근무유형'!H17) -> 15:00
B19: 12 | C19: =IF(OR('2-1.근무유형'!E18="",LEFT('2-1.근무유형'!E18,1)="("),"",'2-1.근무유형'!E18) -> B(07:00-16:00) | D19: =IF(OR('2-1.근무유형'!G18="",'2-1.근무유형'!H18=""),"",'2-1.근무유형'!G18&"-"&'2-1.근무유형'!H18) -> 07:00-16:00 | E19: =IF('2-1.근무유형'!G18="","",'2-1.근무유형'!G18) -> 07:00 | H19: =IF('2-1.근무유형'!H18="","",'2-1.근무유형'!H18) -> 16:00
... B47: 40 | C47: =IF(OR('2-1.근무유형'!E46="",LEFT('2-1.근무유형'!E46,1)="("),"",'2-1.근무유형'!E46) | D47: =IF(OR('2-1.근무유형'!G46="",'2-1.근무유형'!H46=""),"",'2-1.근무유형'!G46&"-"&'2-1.근무유형'!H46) | E47: =IF('2-1.근무유형'!G46="","",'2-1.근무유형'!G46) | H47: =IF('2-1.근무유형'!H46="","",'2-1.근무유형'!H46)

Sheet 3.근로유형(정산)
B2: 3. 근로유형(정산) 정의 - 소정근로 / 연장 / 대체휴가 기준
B4: [근로유형이란] 근무유형(Day)이 하루의 스케줄이라면, 근로유형은 그 근무를 어떤 기준으로 정산할지를 정의합니다. 일 / 주 소정근로시간, 법정근로시간 대비 초과분(연장) 산정 방식이 여기에 연동됩니다. [HCG 설정안] BYN은 사무직 / 생산직 구분이 없어 표준 근로를 기본 하나로 통일하고, 모성보호 단축근무만 단축시간별로 분리하였습니다. 육아기 근로시간 단축은 법정상 주 15~35시간 범위에서 개인별로 신청하므로, 실제 운영 중이거나 예정인 단축시간을 회신해 주시면 해당 유형만 생성하겠습니다.
B6: 3-1. 근로유형 목록 / 연장 인정 기준
B7: [회신 요청] 연장 인정시간에는 해당 근로유형에서 연장근로를 인정하는 1일 최대 시간을 숫자로 기재해 주십시오. 연장 운영이 없는 유형은 반드시 0을 입력해 주십시오. (공란과 0은 다르게 처리됩니다) 연장근로 처리구분은 (1) 급여수당만 - 연장시간 전액을 수당으로 지급 (2) 급여수당 + 대체휴가(미확정) - 수당 지급과 대체휴가 부여를 선택할 수 있도록 미확정 상태로 적재 중에서 선택해 주십시오. [확인 필요] 본사 / 물류는 고정연장수당(포괄임금), 제주 야크마을은 실적 기준 정산으로 파악됩니다. 정산 기준이 다르다면 제주용 근로유형을 별도로 분리해야 하므로 회신 부탁드립니다.
B8: No | C8: 사용여부 (선택) | D8: 근로유형 명칭 | E8: 일 소정 근로시간 | F8: 주 소정 근로시간 | G8: 연장 시간 (없으면 0) | H8: 연장근로 처리구분 | I8: 비고 (적용 대상 / 근거)
B9: 1 | C9: ☑ | D9: 기본 | E9: 8 | F9: 40 | G9: 12 | H9: 급여수당+대체휴가(미확정)
B10: 2 | C10: ☑ | D10: 임신기단축(2시간) | E10: 6 | F10: 30 | G10: 0 | H10: 연장 미운영
B11: 3 | C11: ☑ | D11: 육아기단축(7.00) | E11: 7 | F11: 35 | G11: 0 | H11: 연장 미운영
B12: 4 | C12: ☑ | D12: 육아기단축(6.00) | E12: 6 | F12: 30 | G12: 0 | H12: 연장 미운영
B13: 5 | C13: ☑ | D13: 육아기단축(5.00) | E13: 5 | F13: 25 | G13: 0 | H13: 연장 미운영
B14: 6 | C14: ☐ | D14: (추가하실 근로유형을 작성해 주세요)
B15: 7 | C15: ☐ | D15: (추가하실 근로유형을 작성해 주세요)
B16: 8 | C16: ☐ | D16: (추가하실 근로유형을 작성해 주세요)
B17: 9 | C17: ☐ | D17: (추가하실 근로유형을 작성해 주세요)
B18: 10 | C18: ☐ | D18: (추가하실 근로유형을 작성해 주세요)
B20: 3-2. 대체휴가 부여 기준
B21: [회신 요청] 연장 / 야간 / 휴일근로 누적시간을 몇 시간 모았을 때 대체휴가를 며칠 부여할지 기준을 기재해 주십시오. 가산율 적용 여부(연장 1시간을 1.5시간으로 환산할지)도 함께 선택 부탁드립니다. 예) 8시간 => 1일 / 4시간 => 0.5일. 대체휴가는 근태코드 6100(대체휴무)로 적재되며, 사용기한 경과분의 처리 방식(수당 전환 / 소멸)도 회신 요청드립니다. [참고] 제주 야크마을 근무표에는 이월휴무 / 당월휴무 / 잔여휴무가 별도로 관리되고 있습니다. 현행 운영 기준을 함께 알려주시면 반영하겠습니다.
B22: No | C22: 사용여부 (선택) | D22: 적용 근로유형 | E22: 누적 연장시간 (시간) | F22: 부여 일수 (일) | G22: 가산율 적용 여부 | H22: 사용기한 | I22: 비고
B23: 1 | C23: ☐ | D23: 기본 | E23: 2 | F23: 0.25 | G23: N | H23: 발생 후 3개월이내
B24: 2 | C24: ☐
B25: 3 | C25: ☐
B26: 4 | C26: ☐
B27: 5 | C27: ☐
B28: 6 | C28: ☐

Sheet 4.스케줄근무그룹
B2: 4. 스케줄근무그룹 - 스케줄근무 운영 단위 확인
B4: [스케줄근무그룹이란] 교대제와 같이 날짜별로 근무유형이 바뀌는 스케줄근무를 운영하는 단위입니다. 그룹 안에 소속된 직원에게 월 단위로 근무유형(Day)을 배정하여 근무표를 편성합니다. [회신 요청] 스케줄근무를 운영해야 하는 근무유형을 그룹별로 반영해 주십시오. 그룹에서 사용할 근무유형이 2-1 목록과 다르거나 누락된 경우 해당 칸에 직접 기재해 주십시오. [HCG 설정안] 제주 야크마을 2026년 7월 근무표를 기준으로 파트 단위 5개 그룹을 구성하였습니다. 경영지원팀은 D(09:00-18:00) 일근으로 확인되어 스케줄근무그룹에서 제외하였습니다. 그룹 단위가 파트 기준이 맞는지, 그룹을 통합하거나 더 나눌 필요가 있는지 함께 회신 부탁드립니다.
B6: No | C6: 사용여부 (선택) | D6: 스케줄근무그룹명 | E6: 적용 사업장 | F6: 운영 근무유형 (2-1 기준) | G6: 비고 / 수정요청
B7: 1 | C7: ☑ | D7: 프런트 | E7: 제주 야크마을 | F7: B / C / D / E / F / I(14:00-23:00) / R
B8: 2 | C8: ☑ | D8: 객실관리 | E8: 제주 야크마을 | F8: B / C / C1 / D / F / H
B9: 3 | C9: ☑ | D9: 식음조리 | E9: 제주 야크마을 | F9: A / B / C / D / E / F / G / I(13:00-22:00)
B10: 4 | C10: ☑ | D10: 식음서비스1팀 | E10: 제주 야크마을 | F10: A / B / B1 / C / C1 / D / G
B11: 5 | C11: ☑ | D11: 시스템&시설 | E11: 제주 야크마을 | F11: 주(09:00-18:00) / 야(13:00-익일09:00) / 비(비번)
B12: 6 | C12: ☐ | D12: (추가하실 스케줄근무그룹을 작성해 주세요)
B13: 7 | C13: ☐ | D13: (추가하실 스케줄근무그룹을 작성해 주세요)
B14: 8 | C14: ☐ | D14: (추가하실 스케줄근무그룹을 작성해 주세요)
B15: 9 | C15: ☐ | D15: (추가하실 스케줄근무그룹을 작성해 주세요)
B16: 10 | C16: ☐ | D16: (추가하실 스케줄근무그룹을 작성해 주세요)

Sheet 5.신청서_근태코드
B2: 5. 근태 신청서 정의 / 신청서별 근태코드 연결
B4: [신청서-근태코드 연결이란] 직원이 근태를 신청할 때 사용하는 전자결재 양식(신청서)과, 그 양식에서 선택할 수 있는 근태코드를 연결하는 작업입니다. 연결되지 않은 근태코드는 해당 신청서에서 선택할 수 없습니다. [HCG 설정안] 현재 근태코드에 설정된 신청서유형을 기준으로 정리하였습니다. [회신 요청] 신청서 명칭과 연결 근태코드를 확인해 주시고, 수정이 필요하면 노란색 칸에 기재해 주십시오. 결재선(단계)도 함께 회신 부탁드립니다. 휴직(육아 / 가족돌봄 / 병역 / 일반)과 산재요양은 인사팀 직접 등록 대상으로 보아 신청서에서 제외하였습니다. 직원 신청이 필요하면 회신해 주십시오.
B6: No | C6: 사용여부 (선택) | D6: 신청서 명칭 | E6: 근태코드 1 | F6: 근태코드 2 | G6: 근태코드 3 | H6: 근태코드 4 | I6: 근태코드 5 | J6: 근태코드 6 | K6: 비고
B7: 1 | C7: ☑ | D7: 연차휴가 신청서 | E7: 연차휴가 | F7: 반차(오전) | G7: 반차(오후) | H7: 대체휴무
B8: 2 | C8: ☑ | D8: 경조금/휴가 신청서 | E8: 경조휴가
B9: 3 | C9: ☑ | D9: 근태/휴가 신청서 | E9: 공가 | F9: 생리휴가
B10: 4 | C10: ☑ | D10: 모성보호 신청서 | E10: 출산전후휴가 | F10: 유산/사산휴가 | G10: 배우자출산휴가 | H10: 난임휴가 | I10: 가족돌봄휴가
B11: 5 | C11: ☑ | D11: 출장/외근 신청서 | E11: 출장 | F11: 교육
B12: 6 | C12: ☑ | D12: 근태/휴가취소 신청서 | K12: 취소 가능 근태코드 범위 회신 요청
B13: 7 | C13: ☐ | D13: (추가하실 신청서를 작성해 주세요)
B14: 8 | C14: ☐ | D14: (추가하실 신청서를 작성해 주세요)
B15: 9 | C15: ☐ | D15: (추가하실 신청서를 작성해 주세요)
B16: 10 | C16: ☐ | D16: (추가하실 신청서를 작성해 주세요)
B17: 11 | C17: ☐ | D17: (추가하실 신청서를 작성해 주세요)
B18: 12 | C18: ☐ | D18: (추가하실 신청서를 작성해 주세요)
B19: 13 | C19: ☐ | D19: (추가하실 신청서를 작성해 주세요)

Sheet 참조_근태코드
B2: 참조 - 근태코드 목록 (드롭다운 원본 / 수정 금지)
B3: 근태코드 | C3: 코드명 | D3: 근태(일) | E3: 근무(시간) | F3: 차감근태 | G3: 현행 신청서유형
B4: 4100 | C4: 연차휴가 | D4: Y | E4: N | F4: 연차휴가 | G4: 연차휴가 신청서, 근태/휴가취소 신청서
B5: 4110 | C5: 반차(오전) | D5: Y | E5: N | F5: 연차휴가 | G5: 연차휴가 신청서, 근태/휴가취소 신청서
B6: 4120 | C6: 반차(오후) | D6: Y | E6: N | F6: 연차휴가 | G6: 연차휴가 신청서, 근태/휴가취소 신청서
B7: 6100 | C7: 대체휴무 | D7: Y | E7: N | F7: 대체휴무 | G7: 연차휴가 신청서, 근태/휴가취소 신청서
B8: 5000 | C8: 경조휴가 | D8: Y | E8: N | G8: 경조금/휴가 신청서, 근태/휴가취소 신청서
B9: 5100 | C9: 공가 | D9: Y | E9: N | G9: 근태/휴가 신청서
B10: 5200 | C10: 생리휴가 | D10: Y | E10: N | G10: 근태/휴가 신청서, 근태/휴가취소 신청서
B11: 5300 | C11: 출산전후휴가 | D11: Y | E11: N
B12: 5310 | C12: 유산/사산휴가 | D12: Y | E12: N
B13: 5400 | C13: 배우자출산휴가 | D13: Y | E13: N
B14: 5500 | C14: 난임휴가 | D14: Y | E14: N
B15: 5800 | C15: 가족돌봄휴가 | D15: Y | E15: N
B16: 2000 | C16: 교육 | D16: N | E16: Y | G16: 출장/외근 신청서, 근태/휴가취소 신청서
B17: 2100 | C17: 출장 | D17: Y | E17: N | G17: 출장/외근 신청서, 근태/휴가취소 신청서
